Workbook

Sheet Start
A1: CIO Monthly — input template
A3: Fills the CIO Monthly slides on the dashboard without the published PDF.
A5: 1. Fill the yellow cells on Report, Pension, OPEB, Markets, Macro and Items.
A6: Percent as printed (0.1 means 0.1%); money in $ millions. Leave a cell empty when the report has no figure.
A7: 2. Open Checks: every line should say OK.
A8: 3. Open Export, then File > Save As > "CSV UTF-8 (Comma delimited)". Excel saves only the Export tab.
A9: 4. On the dashboard's CIO Monthly tab choose "Open a template file" and pick the CSV.
A10: It is read in your browser only: nothing is uploaded, and it is cleared when you close or reload the page.
A12: Before LACERA publishes a report, its figures are confidential. Keep this workbook and its CSV on your
A13: team's systems. Do not use the GitHub "CIO report" form for them, and do not send them to AI tools.
A15: Format cio-template-1. Column meanings: docs/cio-template.md in the project on GitHub.

Sheet Report
A1: Report
A2: Dates as YYYY-MM-DD. Data through is the month end the fund figures are as of.
A4: Report (meeting) date | C4: 46246
A5: Data through (month end) | C5: 46203
A6: Market table as of | C6: 46234

Sheet Pension
A1: Pension
A2: Yellow cells are inputs. Percent as printed (0.1 means 0.1%); money in $ millions.
A4: Total market value ($ millions) | C4: 93916
A5: Cash and equivalents ($ millions) | C5: 1309
A6: Growth of $1, trailing 5 years (optional) | C6: 1.43
A8: Performance (% net of fees) | C8: 1M | D8: 3M | E8: FYTD | F8: YTD | G8: 1Y | H8: 3Y | I8: 5Y | J8: 10Y
A9: Total Fund — net return | C9: 0.1 | D9: 5.3 | E9: 12.2 | F9: 5.9 | G9: 12.2 | H9: 10.3 | I9: 7.4 | J9: 9.1
A10: Total Fund — policy benchmark | C10: -1.4 | D10: 5.3 | E10: 14.8 | F10: 5.6 | G10: 14.8 | H10: 11.9 | I10: 7 | J10: 8.6
A11: Total Fund — actuarial hurdle | C11: 0.6 | D11: 1.7 | E11: 7 | F11: 3.4 | G11: 7 | H11: 7 | I11: 7 | J11: 7
A12: Growth — return | C12: -0.1 | D12: 9.5 | E12: 17.5 | F12: 8.1 | G12: 17.5 | H12: 13.9 | I12: 9.8
A13: Growth — benchmark | C13: -2.9 | D13: 8.1 | E13: 23.3 | F13: 7.8 | G13: 23.3 | H13: 18.1 | I13: 10.4
A14: Credit — return | C14: 0.9 | D14: 3.5 | E14: 6.7 | F14: 5.6 | G14: 6.7 | H14: 12.8 | I14: 8.2
A15: Credit — benchmark | C15: 0.6 | D15: 2.2 | E15: 6.8 | F15: 2.5 | G15: 6.8 | H15: 9.2 | I15: 5
A16: Real Assets & Inflation Hedges — return | C16: -1.1 | D16: -0.4 | E16: 7.9 | F16: 3.5 | G16: 7.9 | H16: 4.4 | I16: 5.4
A17: Real Assets & Inflation Hedges — benchmark | C17: -1 | D17: 6 | E17: 11.8 | F17: 7.4 | G17: 11.8 | H17: 5.3 | I17: 5.5
A18: Risk Reduction & Mitigation — return | C18: 0.5 | D18: 0.8 | E18: 5.5 | F18: 1.9 | G18: 5.5 | H18: 4.7 | I18: 1.3
A19: Risk Reduction & Mitigation — benchmark | C19: 0.4 | D19: 1 | E19: 4.5 | F19: 1.4 | G19: 4.5 | H19: 4.3 | I19: 0.9
A21: Allocation | B21: Label (other line only) | C21: Market value $M | D21: Weight % | E21: Target % | F21: Month flow $M
A22: Growth | C22: 45687 | D22: 48.6 | E22: 48 | F22: 41
A23: Credit | C23: 11749 | D23: 12.5 | E23: 13 | F23: -79
A24: Real Assets & Inflation Hedges | C24: 13501 | D24: 14.4 | E24: 15 | F24: -4
A25: Risk Reduction & Mitigation | C25: 22354 | D25: 23.8 | E25: 24 | F25: 0
A26: Other line (overlays, other assets, unitemized; optional) | B26: Overlays & Hedges + Other Asset | C26: 624 | D26: 0.7 | F26: -18
A27: Sum (should match the total and 100%) | C27: =SUM(C22:C26) -> 93915 | D27: =SUM(D22:D26) -> 100 | F27: =SUM(F22:F26) -> -60
A29: Overlay programs (Total Fund only, $ millions) | B29: Program | C29: Month gain | D29: Since inception
B30: Currency hedge | C30: 17.6 | D30: 1563.7
B31: Cash / rebalance overlay | C31: -6.4 | D31: 804.3
A35: Return distribution, last 120 months (% per month) | B35: Bin | C35: Months
B36: ≤ -6 | C36: 1
B37: -6 to -5 | C37: 0
B38: -5 to -4 | C38: 1
B39: -4 to -3 | C39: 3
B40: -3 to -2 | C40: 6
B41: -2 to -1 | C41: 10
B42: -1 to 0 | C42: 11
B43: 0 to 1 | C43: 24
B44: 1 to 2 | C44: 37
B45: 2 to 3 | C45: 17
B46: 3 to 4 | C46: 6
B47: 4 to 5 | C47: 3
...

Sheet OPEB
A1: OPEB
A2: Yellow cells are inputs. Percent as printed (0.1 means 0.1%); money in $ millions.
A4: Total market value ($ millions) | C4: 6447
A5: Cash and equivalents ($ millions) | C5: 145
A6: Growth of $1, trailing 5 years (optional) | C6: 1.37
A8: Performance (% net of fees) | C8: 1M | D8: 3M | E8: FYTD | F8: YTD | G8: 1Y | H8: 3Y | I8: 5Y | J8: 10Y
A9: Total Fund — net return | C9: 0.2 | D9: 7.6 | E9: 14.4 | F9: 7.2 | G9: 14.4 | H9: 12.2 | I9: 6.5 | J9: 9.5
A10: Total Fund — policy benchmark | C10: -0.6 | D10: 6.4 | E10: 14 | F10: 6.1 | G10: 14 | H10: 11.6 | I10: 6 | J10: 8.5
A11: Total Fund — actuarial hurdle | C11: 0.5 | D11: 1.5 | E11: 6.2 | F11: 3.1 | G11: 6.2 | H11: 6.2 | I11: 6.1 | J11: 6
A12: Growth — return | C12: -0.2 | D12: 14.4 | E12: 24.7 | F12: 12 | G12: 24.7 | H12: 19.8 | I12: 10.9
A13: Growth — benchmark | C13: -1.3 | D13: 12.9 | E13: 24.2 | F13: 10.7 | G13: 24.2 | H13: 19.5 | I13: 10.4
A14: Credit — return | C14: 0.2 | D14: 1.9 | E14: 5.9 | F14: 1.8 | G14: 5.9 | H14: 7.4 | I14: 4.3
A15: Credit — benchmark | C15: 0.6 | D15: 2.2 | E15: 6.8 | F15: 2.5 | G15: 6.8 | H15: 8.9 | I15: 4.9
A16: Real Assets & Inflation Hedges — return | C16: 1.7 | D16: 5.9 | E16: 12 | F16: 8.9 | G16: 12 | H16: 8 | I16: 4.3
A17: Real Assets & Inflation Hedges — benchmark | C17: -1.7 | D17: 1 | E17: 9.3 | F17: 4.6 | G17: 9.3 | H17: 4.7 | I17: 2.3
A18: Risk Reduction & Mitigation — return | C18: 0.4 | D18: 0.7 | E18: 3.8 | F18: 0.9 | G18: 3.8 | H18: 3.3 | I18: 0.3
A19: Risk Reduction & Mitigation — benchmark | C19: 0.4 | D19: 0.7 | E19: 3.7 | F19: 0.7 | G19: 3.7 | H19: 3.1 | I19: -0.2
A21: Allocation | B21: Label (other line only) | C21: Market value $M | D21: Weight % | E21: Target % | F21: Month flow $M
A22: Growth | C22: 2910 | D22: 45.2 | E22: 45 | F22: 77
A23: Credit | C23: 1016 | D23: 15.8 | E23: 16 | F23: 24
A24: Real Assets & Inflation Hedges | C24: 845 | D24: 13.1 | E24: 13 | F24: -30
A25: Risk Reduction & Mitigation | C25: 1670 | D25: 25.9 | E25: 26 | F25: 41
A26: Other line (overlays, other assets, unitemized; optional) | B26: Not itemized (report total less listed composites) | C26: 6 | D26: 0 | F26: 0
A27: Sum (should match the total and 100%) | C27: =SUM(C22:C26) -> 6447 | D27: =SUM(D22:D26) -> 100 | F27: =SUM(F22:F26) -> 112
A29: Overlay programs (Total Fund only, $ millions) | B29: Program | C29: Month gain | D29: Since inception
A35: Return distribution, last 120 months (% per month) | B35: Bin | C35: Months
B36: ≤ -6 | C36: 3
B37: -6 to -5 | C37: 2
B38: -5 to -4 | C38: 2
B39: -4 to -3 | C39: 5
B40: -3 to -2 | C40: 9
B41: -2 to -1 | C41: 8
B42: -1 to 0 | C42: 5
B43: 0 to 1 | C43: 18
B44: 1 to 2 | C44: 31
B45: 2 to 3 | C45: 15
B46: 3 to 4 | C46: 10
B47: 4 to 5 | C47: 4
... B56: Latest month | C56: 0.2
A58: Geographic exposure (optional) | C58: Share % | D58: Markets
...

Sheet Markets
A1: Market table (index total returns, %)
A2: One row per index, grouped as the report groups them.
A4: Group | B4: Index | C4: Description | D4: 1M | E4: 3M | F4: FYTD | G4: YTD | H4: 1Y | I4: 3Y | J4: 5Y | K4: 10Y
A5: Reference portfolio | B5: 60:40 Equity:Bond | C5: 60% MSCI ACWI IMI / 40% Bloomberg U.S. Aggregate | D5: -0.7 | E5: 2.2 | F5: -0.7 | G5: 6.6 | H5: 14.3 | I5: 12.1 | J5: 6.1 | K5: 7.9
A6: Global equity | B6: U.S. Large Cap | C6: S&P 500 Total Return | D6: -0.1 | E6: 4.2 | F6: -0.1 | G6: 10.1 | H6: 19.6 | I6: 19.3 | J6: 12.9 | K6: 15.1
A7: Global equity | B7: U.S. Small Cap | C7: Russell 2000 Total Return | D7: -3 | E7: 5 | F7: -3 | G7: 18.9 | H7: 34.2 | I7: 15.1 | J7: 7.1 | K7: 10.6
A8: Global equity | B8: Non-U.S. All Cap | C8: MSCI ACWI ex-U.S. IMI Total Return | D8: 0.2 | E8: 4 | F8: 0.2 | G8: 13.3 | H8: 27.1 | I8: 16.9 | J8: 8.8 | K8: 9.3
A9: Global equity | B9: Emerging Markets | C9: MSCI Emerging Markets Total Return | D9: -3.1 | E9: 4.8 | F9: -3.1 | G9: 20 | H9: 36.4 | I9: 19.3 | J9: 8 | K9: 9.2
A10: Private equity | B10: Private Equity Buyout | C10: Thomson Reuters PE Buyout Index | D10: -0.5 | E10: 6.5 | F10: -0.5 | G10: 11.8 | H10: 22.3 | I10: 24.3 | J10: 8.6 | K10: 13.4
A11: Fixed income | B11: U.S. Corporate High Yield | C11: Bloomberg U.S. Corporate High Yield Total Return | D11: -0.2 | E11: 0.5 | F11: -0.2 | G11: 1.7 | H11: 5.2 | I11: 8.3 | J11: 4 | K11: 5.5
A12: Fixed income | B12: U.S. Long-Term Treasuries | C12: Bloomberg Long Term U.S. Treasury Total Return | D12: -4 | E12: -2.5 | F12: -4 | G12: -3.6 | H12: -0.3 | I12: -1.1 | J12: -7 | K12: -2
A13: Fixed income | B13: DM Leveraged Loans | C13: Credit Suisse Leveraged Loan Total Return | D13: 0.8 | E13: 1.4 | F13: 0.8 | G13: 2.2 | H13: 4.3 | I13: 7.4 | J13: 6.1 | K13: 5.4
A14: Real assets & inflation hedges | B14: Natural Resources | C14: S&P Global Natural Resources Total Return | D14: 7.5 | E14: -1.8 | F14: 7.5 | G14: 17.9 | H14: 37 | I14: 11.8 | J14: 11 | K14: 10.7
A15: Real assets & inflation hedges | B15: Global Infrastructure | C15: Dow Jones Brookfield Global Infrastructure Composite | D15: 1.1 | E15: -2 | F15: 1.1 | G15: 12.2 | H15: 15.8 | I15: 13.3 | J15: 8.5 | K15: 7
A16: Real assets & inflation hedges | B16: TIPS 0–5 Years | C16: Bloomberg U.S. Treasury TIPS 0–5 Years Total Return | D16: 0.2 | E16: -0.1 | F16: 0.2 | G16: 1.8 | H16: 3.5 | I16: 5 | J16: 3.1 | K16: 3.1
A17: Real assets & inflation hedges | B17: Real Estate (ODCE, net)¹ | C17: NCREIF Fund Index – ODCE (Net), latest available quarter | D17: 0 | E17: 1.3 | F17: 0 | G17: 2.3 | H17: 3.6 | I17: -1.4 | J17: 1.9 | K17: 3.7

Sheet Macro
A1: Macro strip
A2: Label, value as shown on the slide, and a detail line with its source or page.
A4: Label | B4: Value | C4: Detail
A5: PCE inflation, June 2026 | B5: 3.7% y/y | C5: Core 3.3% (FRED · BEA). Easing driven largely by a temporary drop in energy prices after the mid-June ceasefire, since reversed (p. 4)
A6: Federal funds target range | B6: 3.50–3.75% | C6: In effect since Dec 11, 2025 (FRED · Federal Reserve). Fifth consecutive pause; three dissents in favor of an increase (p. 4)
A7: Unemployment and participation, June 2026 | B7: 4.2% · 61.5% | C7: Unemployment rate · labor force participation rate (FRED · BLS)
A8: Treasury yields, Jun 30, 2026 | B8: 3.9 · 4.1 · 4.2 · 4.4 · 4.9% | C8: 3M · 2Y · 5Y · 10Y · 30Y constant maturity (FRED · Federal Reserve)
A9: U.S. Dollar Index, YTD to 7/31 | B9: +1.6% | C9: GBP +0.1 · EUR −1.9 · JPY −0.4 · CAD −2.1 · MXN +3.8 · CNY +3.5 (p. 6)
A10: Themes to watch | B10: Tariffs · AI · rates | C10: Tariffs of 10–12.5% now cover over 99% of U.S. imports; Strait of Hormuz disruption; Q2 earnings beat with AI capex in focus (p. 4)

Sheet Items
A1: Items for attention
A2: Area, the item as it should read, its status and the report page (optional).
A4: Area | B4: Item | C4: Status | D4: Page
A5: Total Fund | B5: April 2024 approved Strategic Asset Allocation implementation | C5: In progress | D5: 19
A6: Total Fund | B6: Adhering to the BOI-approved 2026 Strategic Framework | C6: In progress | D6: 19
A7: Total Fund | B7: Planning for the Strategic Framework and Initiatives Refresh | C7: In progress | D7: 19
A8: Total Fund | B8: Risk system onboarding | C8: In progress | D8: 19
A9: OPEB Master Trust | B9: April 2024 approved Strategic Asset Allocation implementation | C9: In progress | D9: 19
A10: OPEB Master Trust | B10: Risk system onboarding | C10: In progress | D10: 19
A11: Investments Division | B11: Principal Investment Officer — 1 position | C11: In development | D11: 19
A12: Investments Division | B12: Finance Analyst III — 5 positions | C12: In development | D12: 19
A13: Investments Division | B13: Finance Analyst II — 1 position | C13: In progress | D13: 19
A14: Investments Division | B14: Finance Analyst Fellowship — 2 positions | C14: Completed | D14: 19
A15: Manager update | B15: Acadian Asset Management (global equities separate account, $1,023 mm): Alexandre Voitenok appointed co-Chief Investment Officer effective January 1, 2027, after serving as Deputy CIO since 2024 | C15: For attention | D15: 20
A16: Consultant search | B16: Real Estate Consultant RFP launched Q1 2026, diligence Q1–Q3 2026 — quiet period for respondents (Albourne, Mercer, NEPC, RCLCO, StepStone, Meketa) | C16: Quiet period | D16: 24

Sheet Checks
A1: Checks
A2: The report's own identities. Every line should say OK before you export.
A4: Check | B4: Value | C4: Result
A5: Data through is a month end | B5: =Report!C5 -> 46203 | C5: =IF(AND(ISNUMBER(Report!C5),EOMONTH(Report!C5,0)=Report!C5),"OK","CHECK") -> OK
A6: Report date is on or after data through | B6: =Report!C4 -> 46246 | C6: =IF(AND(ISNUMBER(Report!C4),Report!C4>=Report!C5),"OK","CHECK") -> OK
A7: Pension Fund: total market value and cash entered | B7: =COUNT(Pension!C4,Pension!C5) -> 2 | C7: =IF(COUNT(Pension!C4,Pension!C5)=2,"OK","CHECK") -> OK
A8: Pension Fund: Total Fund return and benchmark for 1M, FYTD and 1Y | B8: =COUNT(Pension!C9,Pension!E9,Pension!G9,Pension!C10,Pension!E10,Pension!G10) -> 6 | C8: =IF(COUNT(Pension!C9,Pension!E9,Pension!G9,Pension!C10,Pension!E10,Pension!G10)=6,"OK","CHECK") -> OK
A9: Pension Fund: every return has a benchmark for the same period | B9: =SUMPRODUCT(--((Pension!C12:J12="")<>(Pension!C13:J13="")))+SUMPRODUCT(--((Pension!C14:J14="")<>(Pension!C15:J15="")))+SUMPRODUCT(--((Pension!C16:J16="")<>(Pension!C17:J17="")))+SUMPRODUCT(--((Pension!C18:J18="")<>(Pension!C19:J19="")))+SUMPRODUCT(--((Pension!C9:J9="")<>(Pension!C10:J10=""))) -> 0 | C9: =IF(SUMPRODUCT(--((Pension!C12:J12="")<>(Pension!C13:J13="")))+SUMPRODUCT(--((Pension!C14:J14="")<>(Pension!C15:J15="")))+SUMPRODUCT(--((Pension!C16:J16="")<>(Pension!C17:J17="")))+SUMPRODUCT(--((Pension!C18:J18="")<>(Pension!C19:J19="")))+SUMPRODUCT(--((Pension!C9:J9="")<>(Pension!C10:J10="")))=0,"OK","CHECK") -> OK
A10: Pension Fund: category weights add to 100% (±0.3) | B10: =SUM(Pension!D22:D26) -> 100 | C10: =IF(ABS(SUM(Pension!D22:D26)-100)<=0.3,"OK","CHECK") -> OK
A11: Pension Fund: category market values add to the total | B11: =SUM(Pension!C22:C26) -> 93915 | C11: =IF(AND(ISNUMBER(Pension!C4),ABS(SUM(Pension!C22:C26)-Pension!C4)<=MAX(2,0.003*Pension!C4)),"OK","CHECK") -> OK
A12: Pension Fund: 14 bin counts add to 120 months | B12: =SUM(Pension!C36:C49) -> 120 | C12: =IF(AND(COUNT(Pension!C36:C49)=14,SUM(Pension!C36:C49)=120),"OK","CHECK") -> OK
A13: Pension Fund: six distribution statistics entered | B13: =COUNT(Pension!C51:C56) -> 6 | C13: =IF(COUNT(Pension!C51:C56)=6,"OK","CHECK") -> OK
A14: Pension Fund: DM + EM shares add to 100% (if geography entered) | B14: =SUM(Pension!C59:C60) -> 100 | C14: =IF(COUNT(Pension!C59:C60)=0,"OK",IF(AND(COUNT(Pension!C59:C60)=2,ABS(SUM(Pension!C59:C60)-100)<=0.2),"OK","CHECK")) -> OK
A15: OPEB Trust: total market value and cash entered | B15: =COUNT(OPEB!C4,OPEB!C5) -> 2 | C15: =IF(COUNT(OPEB!C4,OPEB!C5)=2,"OK","CHECK") -> OK
A16: OPEB Trust: Total Fund return and benchmark for 1M, FYTD and 1Y | B16: =COUNT(OPEB!C9,OPEB!E9,OPEB!G9,OPEB!C10,OPEB!E10,OPEB!G10) -> 6 | C16: =IF(COUNT(OPEB!C9,OPEB!E9,OPEB!G9,OPEB!C10,OPEB!E10,OPEB!G10)=6,"OK","CHECK") -> OK
A17: OPEB Trust: every return has a benchmark for the same period | B17: =SUMPRODUCT(--((OPEB!C12:J12="")<>(OPEB!C13:J13="")))+SUMPRODUCT(--((OPEB!C14:J14="")<>(OPEB!C15:J15="")))+SUMPRODUCT(--((OPEB!C16:J16="")<>(OPEB!C17:J17="")))+SUMPRODUCT(--((OPEB!C18:J18="")<>(OPEB!C19:J19="")))+SUMPRODUCT(--((OPEB!C9:J9="")<>(OPEB!C10:J10=""))) -> 0 | C17: =IF(SUMPRODUCT(--((OPEB!C12:J12="")<>(OPEB!C13:J13="")))+SUMPRODUCT(--((OPEB!C14:J14="")<>(OPEB!C15:J15="")))+SUMPRODUCT(--((OPEB!C16:J16="")<>(OPEB!C17:J17="")))+SUMPRODUCT(--((OPEB!C18:J18="")<>(OPEB!C19:J19="")))+SUMPRODUCT(--((OPEB!C9:J9="")<>(OPEB!C10:J10="")))=0,"OK","CHECK") -> OK
A18: OPEB Trust: category weights add to 100% (±0.3) | B18: =SUM(OPEB!D22:D26) -> 100 | C18: =IF(ABS(SUM(OPEB!D22:D26)-100)<=0.3,"OK","CHECK") -> OK
A19: OPEB Trust: category market values add to the total | B19: =SUM(OPEB!C22:C26) -> 6447 | C19: =IF(AND(ISNUMBER(OPEB!C4),ABS(SUM(OPEB!C22:C26)-OPEB!C4)<=MAX(2,0.003*OPEB!C4)),"OK","CHECK") -> OK
A20: OPEB Trust: 14 bin counts add to 120 months | B20: =SUM(OPEB!C36:C49) -> 120 | C20: =IF(AND(COUNT(OPEB!C36:C49)=14,SUM(OPEB!C36:C49)=120),"OK","CHECK") -> OK
A21: OPEB Trust: six distribution statistics entered | B21: =COUNT(OPEB!C51:C56) -> 6 | C21: =IF(COUNT(OPEB!C51:C56)=6,"OK","CHECK") -> OK
A22: OPEB Trust: DM + EM shares add to 100% (if geography entered) | B22: =SUM(OPEB!C59:C60) -> 100 | C22: =IF(COUNT(OPEB!C59:C60)=0,"OK",IF(AND(COUNT(OPEB!C59:C60)=2,ABS(SUM(OPEB!C59:C60)-100)<=0.2),"OK","CHECK")) -> OK
A23: Market table has its as-of date (if indexes entered) | B23: =COUNTA(Markets!B5:B24) -> 13 | C23: =IF(OR(COUNTA(Markets!B5:B24)=0,ISNUMBER(Report!C6)),"OK","CHECK") -> OK
A24: Every market index has a group | B24: =SUMPRODUCT(--(Markets!B5:B24<>""),--(Markets!A5:A24="")) -> 0 | C24: =IF(SUMPRODUCT(--(Markets!B5:B24<>""),--(Markets!A5:A24=""))=0,"OK","CHECK") -> OK
A26: All checks | C26: =IF(COUNTIF(C5:C24,"OK")=20,"OK","CHECK") -> OK

Sheet Export
A1: section | B1: entity | C1: item | D1: measure | E1: period | F1: value | G1: text
A2: report | C2: format | G2: cio-template-1
A3: report | C3: report_date | G3: =IF(Report!C4="","",YEAR(Report!C4)&"-"&TEXT(MONTH(Report!C4),"00")&"-"&TEXT(DAY(Report!C4),"00")) -> 2026-08-12
A4: report | C4: data_through | G4: =IF(Report!C5="","",YEAR(Report!C5)&"-"&TEXT(MONTH(Report!C5),"00")&"-"&TEXT(DAY(Report!C5),"00")) -> 2026-06-30
A5: report | C5: market_as_of | G5: =IF(Report!C6="","",YEAR(Report!C6)&"-"&TEXT(MONTH(Report!C6),"00")&"-"&TEXT(DAY(Report!C6),"00")) -> 2026-07-31
A6: fund | B6: pension | C6: TOTAL | D6: market_value | F6: =IF(Pension!C4="","",Pension!C4) -> 93916
A7: fund | B7: pension | C7: TOTAL | D7: cash | F7: =IF(Pension!C5="","",Pension!C5) -> 1309
A8: fund | B8: pension | C8: TOTAL | D8: growth_of_dollar | F8: =IF(Pension!C6="","",Pension!C6) -> 1.43
A9: performance | B9: pension | C9: TOTAL | D9: return | E9: 1M | F9: =IF(Pension!C9="","",Pension!C9) -> 0.1
A10: performance | B10: pension | C10: TOTAL | D10: return | E10: 3M | F10: =IF(Pension!D9="","",Pension!D9) -> 5.3
A11: performance | B11: pension | C11: TOTAL | D11: return | E11: FYTD | F11: =IF(Pension!E9="","",Pension!E9) -> 12.2
A12: performance | B12: pension | C12: TOTAL | D12: return | E12: YTD | F12: =IF(Pension!F9="","",Pension!F9) -> 5.9
A13: performance | B13: pension | C13: TOTAL | D13: return | E13: 1Y | F13: =IF(Pension!G9="","",Pension!G9) -> 12.2
A14: performance | B14: pension | C14: TOTAL | D14: return | E14: 3Y | F14: =IF(Pension!H9="","",Pension!H9) -> 10.3
A15: performance | B15: pension | C15: TOTAL | D15: return | E15: 5Y | F15: =IF(Pension!I9="","",Pension!I9) -> 7.4
A16: performance | B16: pension | C16: TOTAL | D16: return | E16: 10Y | F16: =IF(Pension!J9="","",Pension!J9) -> 9.1
A17: performance | B17: pension | C17: TOTAL | D17: benchmark | E17: 1M | F17: =IF(Pension!C10="","",Pension!C10) -> -1.4
A18: performance | B18: pension | C18: TOTAL | D18: benchmark | E18: 3M | F18: =IF(Pension!D10="","",Pension!D10) -> 5.3
A19: performance | B19: pension | C19: TOTAL | D19: benchmark | E19: FYTD | F19: =IF(Pension!E10="","",Pension!E10) -> 14.8
A20: performance | B20: pension | C20: TOTAL | D20: benchmark | E20: YTD | F20: =IF(Pension!F10="","",Pension!F10) -> 5.6
A21: performance | B21: pension | C21: TOTAL | D21: benchmark | E21: 1Y | F21: =IF(Pension!G10="","",Pension!G10) -> 14.8
A22: performance | B22: pension | C22: TOTAL | D22: benchmark | E22: 3Y | F22: =IF(Pension!H10="","",Pension!H10) -> 11.9
A23: performance | B23: pension | C23: TOTAL | D23: benchmark | E23: 5Y | F23: =IF(Pension!I10="","",Pension!I10) -> 7
A24: performance | B24: pension | C24: TOTAL | D24: benchmark | E24: 10Y | F24: =IF(Pension!J10="","",Pension!J10) -> 8.6
A25: performance | B25: pension | C25: TOTAL | D25: hurdle | E25: 1M | F25: =IF(Pension!C11="","",Pension!C11) -> 0.6
A26: performance | B26: pension | C26: TOTAL | D26: hurdle | E26: 3M | F26: =IF(Pension!D11="","",Pension!D11) -> 1.7
A27: performance | B27: pension | C27: TOTAL | D27: hurdle | E27: FYTD | F27: =IF(Pension!E11="","",Pension!E11) -> 7
A28: performance | B28: pension | C28: TOTAL | D28: hurdle | E28: YTD | F28: =IF(Pension!F11="","",Pension!F11) -> 3.4
A29: performance | B29: pension | C29: TOTAL | D29: hurdle | E29: 1Y | F29: =IF(Pension!G11="","",Pension!G11) -> 7
A30: performance | B30: pension | C30: TOTAL | D30: hurdle | E30: 3Y | F30: =IF(Pension!H11="","",Pension!H11) -> 7
A31: performance | B31: pension | C31: TOTAL | D31: hurdle | E31: 5Y | F31: =IF(Pension!I11="","",Pension!I11) -> 7
A32: performance | B32: pension | C32: TOTAL | D32: hurdle | E32: 10Y | F32: =IF(Pension!J11="","",Pension!J11) -> 7
A33: performance | B33: pension | C33: GROWTH | D33: return | E33: 1M | F33: =IF(Pension!C12="","",Pension!C12) -> -0.1
A34: performance | B34: pension | C34: GROWTH | D34: return | E34: 3M | F34: =IF(Pension!D12="","",Pension!D12) -> 9.5
A35: performance | B35: pension | C35: GROWTH | D35: return | E35: FYTD | F35: =IF(Pension!E12="","",Pension!E12) -> 17.5
A36: performance | B36: pension | C36: GROWTH | D36: return | E36: YTD | F36: =IF(Pension!F12="","",Pension!F12) -> 8.1
A37: performance | B37: pension | C37: GROWTH | D37: return | E37: 1Y | F37: =IF(Pension!G12="","",Pension!G12) -> 17.5
A38: performance | B38: pension | C38: GROWTH | D38: return | E38: 3Y | F38: =IF(Pension!H12="","",Pension!H12) -> 13.9
A39: performance | B39: pension | C39: GROWTH | D39: return | E39: 5Y | F39: =IF(Pension!I12="","",Pension!I12) -> 9.8
A40: performance | B40: pension | C40: GROWTH | D40: return | E40: 10Y | F40: =IF(Pension!J12="","",Pension!J12)
...
